<?xml version="1.0"?>
<robot name="origins">
	<link name="base_link">
   		<visual>
     			<geometry>
       				<box size="0 0 0"/>
     			</geometry>
			<origin rpy="0 0 0" xyz="0 0 0"/>
			<material name="white">
				<color rgba="1 1 1 1"/>
			</material>
   		</visual>
		<collision>
			<geometry>
       				<box size="0 0 0"/>
			</geometry>
		</collision>
		<inertial>
			<mass value="100"/>
	 		<inertia ixx="1.0" ixy="0.0" ixz="0.0" iyy="1.0" iyz="0.0" izz="1.0"/>
		</inertial>			
   </link>

   <joint name="joint_1" type="fixed">
    <parent link="base_link"/>
    <child link="link_1"/>
    <origin rpy="0  0  0" xyz="0 0 1"/>
    <axis xyz="0  0  1"/>
    <limit effort="-1.0" lower="-1.79769e+308" upper="1.79769e+308" velocity="-1.0"/>
  </joint>
   
   <link name="link_1">
    <inertial>
      <mass value="1"/>
      <origin rpy="0  0  0" xyz="0  0  0"/>
      <inertia ixx="0.145833" ixy="0" ixz="0" iyy="0.145833" iyz="0" izz="0.125"/>
    </inertial>
    <collision name="Better_Robot_Arm__collision">
      <origin rpy="0  0  0" xyz="0 0 2.5"/>
      <geometry>
        <cylinder length="5" radius="0.5"/>
      </geometry>
    </collision>
    <visual name="Better_Robot_Arm__visual">
      <origin rpy="0  0  0" xyz="0 0 2.5"/>
      <geometry>
        <cylinder length="5" radius="0.3"/>
      </geometry>
    </visual>
  </link>
  
  <joint name="joint_2" type="revolute">
    <parent link="link_1"/>
    <child link="link_2"/>
    <origin rpy="0  0  1" xyz="0 0 5.5"/>
    <axis xyz="0  0  0"/>
    <limit effort="0" lower="0" upper="0" velocity="0"/>
  </joint>
  
  <link name="link_2">
    <inertial>
      <mass value="1"/>
      <origin rpy="0  0  0" xyz="0  0  0"/>
      <inertia ixx="0.166667" ixy="0" ixz="0" iyy="0.166667" iyz="0" izz="0.166667"/>
    </inertial>
    <collision name="Better_Robot_Arm__collision">
      <origin rpy="0  0  0" xyz="0  0  0"/>
      <geometry>
        <box size="1 1 1"/>
      </geometry>
    </collision>
    <visual name="Better_Robot_Arm__visual">
      <origin rpy="0  0  0" xyz="0  0  0"/>
      <geometry>
        <box size="1 1 1"/>
      </geometry>
    </visual>
  </link>

  <joint name="joint_3" type="fixed">
    <parent link="link_2"/>
    <child link="link_3"/>
    <origin rpy="0  1.57  0" xyz="3 0 0"/>
    <axis xyz="0  0  0"/>
    <limit effort="0" lower="0" upper="0" velocity="0"/>
  </joint>

  <link name="link_3">
    <inertial>
      <mass value="1"/>
      <origin rpy="0  0  0" xyz="0  0  0"/>
      <inertia ixx="0.145833" ixy="0" ixz="0" iyy="0.145833" iyz="0" izz="0.125"/>
    </inertial>
    <collision name="Better_Robot_Arm__collision">
      <origin rpy="0  0  0" xyz="0  0  0"/>
      <geometry>
        <cylinder length="5" radius="0.3"/>
      </geometry>
    </collision>
    <visual name="Better_Robot_Arm__visual">
      <origin rpy="0  0  0" xyz="0  0  0"/>
      <geometry>
        <cylinder length="5" radius="0.3"/>
      </geometry>
    </visual>
  </link> 

  <joint name="joint_4" type="fixed">
    <parent link="link_3"/>
    <child link="link_4"/>
    <origin rpy="0   -1.57  0" xyz="2.38000000e-03   0.00000000e+00   3.00000000e+00"/>
    <axis xyz="0  0  0"/>
    <limit effort="0" lower="0" upper="0" velocity="0"/>
  </joint>

  <link name="link_4">
    <inertial>
      <mass value="1"/>
      <origin rpy="0  0  0" xyz="0  0  0"/>
      <inertia ixx="0.145833" ixy="0" ixz="0" iyy="0.145833" iyz="0" izz="0.125"/>
    </inertial>
    <collision name="Better_Robot_Arm__collision">
      <origin rpy="0  0  0" xyz="0  0  0"/>
      <geometry>
        <cylinder length="1" radius="0.5"/>
      </geometry>
    </collision>
    <visual name="Better_Robot_Arm__visual">
      <origin rpy="0  0  0" xyz="0  0  0"/>
      <geometry>
        <cylinder length="1" radius="0.5"/>
      </geometry>
    </visual>
  </link>

  <joint name="joint_5" type="revolute">
    <parent link="link_4"/>
    <child link="link_5"/>
    <origin rpy="0  0  0" xyz="1  0  0"/>
    <axis xyz="0  0  1"/>
    <limit effort="-1.0" lower="-1.79769e+308" upper="1.79769e+308" velocity="-1.0"/>
  </joint>

  <link name="link_5">
    <inertial>
      <mass value="1"/>
      <origin rpy="0  0  0" xyz="0  0  0"/>
      <inertia ixx="0.166667" ixy="0" ixz="0" iyy="0.166667" iyz="0" izz="0.166667"/>
    </inertial>
    <collision name="Better_Robot_Arm__collision">
      <origin rpy="0  0  0" xyz="0  0  0"/>
      <geometry>
        <box size="1 1 1"/>
      </geometry>
    </collision>
    <visual name="Better_Robot_Arm__visual">
      <origin rpy="0  0  0" xyz="0  0  0"/>
      <geometry>
        <box size="1 1 1"/>
      </geometry>
    </visual>
  </link>

  <joint name="joint_6" type="prismatic">
    <parent link="link_5"/>
    <child link="link_6"/>
    <origin rpy="0  0  0" xyz="0       0      -0.6"/>
    <axis xyz="1  0  0"/>
    <limit effort="-1.0" lower="-1.79769e+308" upper="1.79769e+308" velocity="-1.0"/>
  </joint>

  <link name="link_6">
    <inertial>
      <mass value="1"/>
      <origin rpy="0  0  0" xyz="0  0  0"/>
      <inertia ixx="0.166667" ixy="0" ixz="0" iyy="0.166667" iyz="0" izz="0.166667"/>
    </inertial>
    <collision name="Better_Robot_Arm__collision">
      <origin rpy="0  0  0" xyz="0  0  0"/>
      <geometry>
        <box size="1 1 0.2"/>
      </geometry>
    </collision>
    <visual name="Better_Robot_Arm__visual">
      <origin rpy="0  0  0" xyz="0  0  0"/>
      <geometry>
        <box size="1 1 0.2"/>
      </geometry>
    </visual>
  </link>

</robot>
