<?xml version="1.0" ?>
<robot name="Better_Robot_Arm">
  <joint name="Better_Robot_Arm__link_0_JOINT_0" type="revolute">
    <parent link="Better_Robot_Arm__link_0"/>
    <child link="Better_Robot_Arm__link_1"/>
    <origin rpy="0  0  0" xyz="-3.28571  0      -1.66429"/>
    <axis xyz="0  0  1"/>
    <limit effort="-1.0" lower="-1.79769e+308" upper="1.79769e+308" velocity="-1.0"/>
  </joint>
  <joint name="Better_Robot_Arm__link_1_JOINT_1" type="fixed">
    <parent link="Better_Robot_Arm__link_1"/>
    <child link="Better_Robot_Arm__link_2"/>
    <origin rpy="0  0  0" xyz="0    0    2.95"/>
    <axis xyz="0  0  0"/>
    <limit effort="0" lower="0" upper="0" velocity="0"/>
  </joint>
  <joint name="Better_Robot_Arm__link_2_JOINT_2" type="fixed">
    <parent link="Better_Robot_Arm__link_2"/>
    <child link="Better_Robot_Arm__link_3"/>
    <origin rpy="0    1.57  0" xyz="2.99999  0       0"/>
    <axis xyz="0  0  0"/>
    <limit effort="0" lower="0" upper="0" velocity="0"/>
  </joint>
  <joint name="Better_Robot_Arm__link_3_JOINT_3" type="fixed">
    <parent link="Better_Robot_Arm__link_3"/>
    <child link="Better_Robot_Arm__link_4"/>
    <origin rpy="0   -1.57  0" xyz="2.38000000e-03   0.00000000e+00   3.00000000e+00"/>
    <axis xyz="0  0  0"/>
    <limit effort="0" lower="0" upper="0" velocity="0"/>
  </joint>
  <joint name="Better_Robot_Arm__link_4_JOINT_4" type="revolute">
    <parent link="Better_Robot_Arm__link_4"/>
    <child link="Better_Robot_Arm__link_5"/>
    <origin rpy="0  0  0" xyz="1  0  0"/>
    <axis xyz="0  0  1"/>
    <limit effort="-1.0" lower="-1.79769e+308" upper="1.79769e+308" velocity="-1.0"/>
  </joint>
  <joint name="Better_Robot_Arm__link_5_JOINT_5" type="prismatic">
    <parent link="Better_Robot_Arm__link_5"/>
    <child link="Better_Robot_Arm__link_6"/>
    <origin rpy="0  0  0" xyz="0       0      -0.59999"/>
    <axis xyz="1  0  0"/>
    <limit effort="-1.0" lower="-1.79769e+308" upper="1.79769e+308" velocity="-1.0"/>
  </joint>
  <link name="Better_Robot_Arm__link_0">
    <inertial>
      <mass value="1"/>
      <origin rpy="0  0  0" xyz="0  0  0"/>
      <inertia ixx="0.145833" ixy="0" ixz="0" iyy="0.145833" iyz="0" izz="0.125"/>
    </inertial>
    <collision name="Better_Robot_Arm__collision">
      <origin rpy="0  0  0" xyz="-3.28571  0      -4.16429"/>
      <geometry>
        <cylinder length="0.1" radius="0.5"/>
      </geometry>
    </collision>
    <visual name="Better_Robot_Arm__visual">
      <origin rpy="0  0  0" xyz="-3.28571  0      -4.16429"/>
      <geometry>
        <cylinder length="0.1" radius="0.5"/>
      </geometry>
    </visual>
  </link>
  <link name="Better_Robot_Arm__link_1">
    <inertial>
      <mass value="1"/>
      <origin rpy="0  0  0" xyz="0  0  0"/>
      <inertia ixx="0.145833" ixy="0" ixz="0" iyy="0.145833" iyz="0" izz="0.125"/>
    </inertial>
    <collision name="Better_Robot_Arm__collision">
      <origin rpy="0  0  0" xyz="0  0  0"/>
      <geometry>
        <cylinder length="4.9" radius="0.5"/>
      </geometry>
    </collision>
    <visual name="Better_Robot_Arm__visual">
      <origin rpy="0  0  0" xyz="0  0  0"/>
      <geometry>
        <cylinder length="4.9" radius="0.5"/>
      </geometry>
    </visual>
  </link>
  <link name="Better_Robot_Arm__link_2">
    <inertial>
      <mass value="1"/>
      <origin rpy="0  0  0" xyz="0  0  0"/>
      <inertia ixx="0.166667" ixy="0" ixz="0" iyy="0.166667" iyz="0" izz="0.166667"/>
    </inertial>
    <collision name="Better_Robot_Arm__collision">
      <origin rpy="0  0  0" xyz="0  0  0"/>
      <geometry>
        <box size="1 1 1"/>
      </geometry>
    </collision>
    <visual name="Better_Robot_Arm__visual">
      <origin rpy="0  0  0" xyz="0  0  0"/>
      <geometry>
        <box size="1 1 1"/>
      </geometry>
    </visual>
  </link>
  <link name="Better_Robot_Arm__link_3">
    <inertial>
      <mass value="1"/>
      <origin rpy="0  0  0" xyz="0  0  0"/>
      <inertia ixx="0.145833" ixy="0" ixz="0" iyy="0.145833" iyz="0" izz="0.125"/>
    </inertial>
    <collision name="Better_Robot_Arm__collision">
      <origin rpy="0  0  0" xyz="0  0  0"/>
      <geometry>
        <cylinder length="5" radius="0.5"/>
      </geometry>
    </collision>
    <visual name="Better_Robot_Arm__visual">
      <origin rpy="0  0  0" xyz="0  0  0"/>
      <geometry>
        <cylinder length="5" radius="0.5"/>
      </geometry>
    </visual>
  </link>
  <link name="Better_Robot_Arm__link_4">
    <inertial>
      <mass value="1"/>
      <origin rpy="0  0  0" xyz="0  0  0"/>
      <inertia ixx="0.145833" ixy="0" ixz="0" iyy="0.145833" iyz="0" izz="0.125"/>
    </inertial>
    <collision name="Better_Robot_Arm__collision">
      <origin rpy="0  0  0" xyz="0  0  0"/>
      <geometry>
        <cylinder length="1" radius="0.5"/>
      </geometry>
    </collision>
    <visual name="Better_Robot_Arm__visual">
      <origin rpy="0  0  0" xyz="0  0  0"/>
      <geometry>
        <cylinder length="1" radius="0.5"/>
      </geometry>
    </visual>
  </link>
  <link name="Better_Robot_Arm__link_5">
    <inertial>
      <mass value="1"/>
      <origin rpy="0  0  0" xyz="0  0  0"/>
      <inertia ixx="0.166667" ixy="0" ixz="0" iyy="0.166667" iyz="0" izz="0.166667"/>
    </inertial>
    <collision name="Better_Robot_Arm__collision">
      <origin rpy="0  0  0" xyz="0  0  0"/>
      <geometry>
        <box size="1 1 1"/>
      </geometry>
    </collision>
    <visual name="Better_Robot_Arm__visual">
      <origin rpy="0  0  0" xyz="0  0  0"/>
      <geometry>
        <box size="1 1 1"/>
      </geometry>
    </visual>
  </link>
  <link name="Better_Robot_Arm__link_6">
    <inertial>
      <mass value="1"/>
      <origin rpy="0  0  0" xyz="0  0  0"/>
      <inertia ixx="0.166667" ixy="0" ixz="0" iyy="0.166667" iyz="0" izz="0.166667"/>
    </inertial>
    <collision name="Better_Robot_Arm__collision">
      <origin rpy="0  0  0" xyz="0  0  0"/>
      <geometry>
        <box size="1 1 0.2"/>
      </geometry>
    </collision>
    <visual name="Better_Robot_Arm__visual">
      <origin rpy="0  0  0" xyz="0  0  0"/>
      <geometry>
        <box size="1 1 0.2"/>
      </geometry>
    </visual>
  </link>
</robot>
